Workbook

Sheet How To
A1: Fox Creek Scratch Strokes Gained (data-anchored)
A2: Green tees, 3,802 yards, par 62. Baseline = a scratch golfer, built from published scratch statistics (Shot Scope, Arccos) rather than tour tables plus guesses. Hole expectations are calibrated so the 18 holes sum to the Course Rating + 2.4, i.e. an average scratch round (the rating itself is a good day).
A4: How to use
A5: 1. Log every shot on 'Shot Log': Round ID, Hole, Start lie, Start distance, End lie, End distance, Penalty.
A6: 2. Lies: T = tee, F = fairway/fringe, R = rough, S = sand, X = recovery (blocked, punch-out), G = green, H = holed.
A7: 3. Distances: yards for T/F/R/S/X, FEET for G. Leave End distance blank when End lie is H. Tee shots on par 4/5 use the hole's tee-model value whatever you enter for distance; par-3 tee shots use the distance you enter.
A8: 4. Penalty: 1 if the shot cost a penalty stroke. For OB, log the re-tee as the next shot from T with Penalty 1.
A9: 5. Each shot's next row starts where the previous one ended. Add the Round ID on 'Rounds' for category totals. Delete the EXAMPLE rows once you have logged a real round.
A11: How the baseline is built (see 'Scratch Data')
A12: Putting: E(putts) = 2 - P(one-putt) + P(three-putt) + P(four-putt), from Shot Scope / Arccos scratch make and three-putt rates by distance.
A13: Approach (50-250 yds): E = 1 + GIR x E(putts from on-green proximity) + (1 - GIR) x E(after a miss), using scratch GIR, proximity and short-game data. Rough and sand use factors on the fairway inputs.
A14: Around the green (<= 50 yds): from scratch up-and-down rates (<25 yds 63%, 25-50 yds 32%, sand save 37%). From 150-250 yds the table takes the better of going for the green and laying up; beyond 250 it is 1 + a layup/advance to a fairway-rough blend.
... A21: Yellow cells with blue text are inputs. Every published number and every assumption is labelled on 'Inputs' and 'Scratch Data'. 'Tour Ref' shows the scratch baseline next to tour values as a sanity check.

Sheet Inputs
A1: Assumptions and parameters
A3: Parameter | B3: Value | C3: Notes / source
A4: COURSE
A5: Course rating (Green tees, men) | B5: 59.9 | C5: PUBLISHED: Golfify / 18Birdies listings for Fox Creek Golf Club, Smyrna GA (Green 3,802 yds, 59.9 / 105). Confirm in the GHIN course lookup.
A6: Good-day gap added to the CR target | B6: 2.4 | C6: DERIVED. A Course Rating is a scratch golfer's good day: a Handicap Index uses the best 8 of 20 differentials, and the mean of the best 8 of 20 normal draws sits 0.93 sigma below the mean. With a scratch round-to-round sigma of ~2.6 strokes, CR + 2.4 is an AVERAGE scratch round, which is what the Shot Scope / Arccos tables describe. Set 0 to calibrate to the CR itself.
A7: Stroke-index weight (0 = spread evenly, 1 = fully by SI) | B7: 0 | C7: How the course adjustment is spread across holes. ASSUMPTION.
A8: Off-green anchor E for spreading the hole adjustment | B8: 1.85 | C8: A shot's share of the hole adjustment = (E - G0)/(E_tee - G0), 0 on the green. 1.85 ~ scratch putts per GIR (Shot Scope). ASSUMPTION.
A9: Teed-ball bonus on par-3 tee shots (strokes) | B9: 0 | C9: Positive = a teed ball is easier than the same yardage from the fairway. Tour data actually runs the other way (par-3 tee shots ~0.1 HARDER than same-length fairway shots, because of guarded greens), so 0 is used and the course calibration absorbs Fox Creek specifics. ASSUMPTION.
A10: APPROACH MODEL
A11: Effective putt-distance factor (Jensen correction) | B11: 0.7 | C11: Proximity varies shot to shot and E(putts) is concave, so E over the spread < E at the mean. Using 0.7 x mean proximity reproduces tour fairway values from tour GIR/proximity to ~0.05. ASSUMPTION.
A12: Rough: GIR factor | B12: 0.8 | C12: GIR from rough = fairway GIR x this. Shot Scope: fairway-vs-rough GIR advantage 'up to 25%'. ASSUMPTION within that.
A13: Rough: proximity factor | B13: 1.25 | C13: On-green proximity from rough = fairway x this. golfity estimate: rough adds 30-40% to proximity. ASSUMPTION.
A14: Rough: extra strokes after a miss | B14: 0.1 | C14: ASSUMPTION.
A15: Fairway bunker (>50 yds): GIR factor | B15: 0.65 | C15: ASSUMPTION.
A16: Fairway bunker: proximity factor | B16: 1.3 | C16: ASSUMPTION.
A17: Fairway bunker: extra strokes after a miss | B17: 0.2 | C17: ASSUMPTION.
A18: Rough around the green: extra strokes vs fairway lie | B18: 0.2 | C18: Chip/pitch from rough vs fairway/fringe. ASSUMPTION.
A19: Fairway share after a layup/advance shot | B19: 0.7 | C19: For shots from >250 yds. ASSUMPTION.
A20: Layup/advance distance from fairway (yds) | B20: 220 | C20: Scratch 3-wood/hybrid from the fairway on a long second shot; a deliberate layup never leaves less than 30 yds. ASSUMPTION.
A21: Advance distance from rough (yds) | B21: 190 | C21: ASSUMPTION.
A22: Advance distance from a fairway bunker (yds) | B22: 170 | C22: ASSUMPTION.
... A24: Recovery: extra strokes | B24: 0.1 | C24: ASSUMPTION.
A25: TEE MODEL
A26: Fairway share of in-play tee shots | B26: 0.7 | C26: In-play tee shots blended 70% fairway / 30% rough. ASSUMPTION.
A27: Default fairway width (yds, tree line to tree line) | B27: 45 | C27: From you: ~45 yds with trees both sides on basically every hole; hole 1 OB both sides; holes 3 and 16 OB right.
A28: Scratch club 1 (driver) distance | B28: 262 | C28: Shot Scope P-avg for scratch is 285 (solid strikes). Plain averages run ~8-10% lower (3H avg 197 vs P-avg 219; Arccos 0-4.9 band 244 all ages). 262 = 285 x 0.92.
A29: Scratch club 1 (driver) sigma % | B29: 0.075 | C29: DERIVED: Arccos (Stagner) 7% of 0-5 index drives finish >40 yds from fairway centre -> sigma ~22 yds; tour 65-70 yd cone -> ~16-18 yds. Scratch ~20 yds = 7.5% of 262.
A30: Scratch club 2 (3-wood) distance | B30: 245 | C30: Shot Scope P-avg 261-267 x 0.92.
A31: Scratch club 2 (3-wood) sigma % | B31: 0.08 | C31: DERIVED: Shot Scope scratch 3-wood hits only ~1% more fairways than driver despite ~18 yds less, implying similar absolute spread (~20 yds) = ~8% of 245.
A32: Scratch club 3 (3-hybrid) distance | B32: 203 | C32: Shot Scope scratch 3H: P-avg 219, plain average 197.
A33: Scratch club 3 (3-hybrid) sigma % | B33: 0.075 | C33: ASSUMPTION (no published figure): ~15 yds.
A34: Scratch club 4 (5-iron) distance | B34: 185 | C34: Shot Scope P-avg 200 x 0.92.
A35: Scratch club 4 (5-iron) sigma % | B35: 0.07 | C35: ASSUMPTION (no published figure): ~13 yds.
A36: Your club 1 (driver) distance | B36: 290 | C36: Your tee clubs for the 'Your best club' columns. Replace sigma % with sim-measured numbers (offline std dev / distance).
A37: Your club 1 (driver) sigma % | B37: 0.1 | C37: PLACEHOLDER.
A38: Your club 2 (7-wood) distance | B38: 215
A39: Your club 2 (7-wood) sigma % | B39: 0.085 | C39: PLACEHOLDER.
A40: Your club 3 (2-iron) distance | B40: 240
A41: Your club 3 (2-iron) sigma % | B41: 0.09 | C41: PLACEHOLDER.
A42: Your club 4 (5-iron) distance | B42: 186
...

Sheet Scratch Data
A1: Scratch-golfer anchor data (blue = editable). Interpolated on 'Baseline'.
A4: Feet | B4: P(1-putt) | C4: P(3-putt) | D4: P(4-putt) | E4: E(putts) | G4: Yards (fairway) | H4: GIR | I4: On-green proximity (ft) | J4: E after a miss | L4: Yards (fairway/fringe lie) | M4: E (strokes to hole out) | O4: Yards (greenside bunker) | P4: E (strokes to hole out)
A5: 1 | B5: 1 | C5: 0 | D5: 0 | E5: =2-B5+C5+D5 -> 1 | G5: 50 | H5: 0.8 | I5: 14 | J5: 2.45 | L5: 5 | M5: 2.18 | O5: 5 | P5: 2.55
A6: 2 | B6: 0.99 | C6: 0 | D6: 0 | E6: =2-B6+C6+D6 -> 1.01 | G6: 75 | H6: 0.75 | I6: 17 | J6: 2.48 | L6: 10 | M6: 2.3 | O6: 10 | P6: 2.62
A7: 3 | B7: 0.94 | C7: 0 | D7: 0 | E7: =2-B7+C7+D7 -> 1.06 | G7: 100 | H7: 0.68 | I7: 21 | J7: 2.5 | L7: 15 | M7: 2.38 | O7: 15 | P7: 2.68
A8: 4 | B8: 0.84 | C8: 0.001 | D8: 0 | E8: =2-B8+C8+D8 -> 1.161 | G8: 125 | H8: 0.62 | I8: 25 | J8: 2.55 | L8: 20 | M8: 2.44 | O8: 20 | P8: 2.75
A9: 5 | B9: 0.73 | C9: 0.002 | D9: 0 | E9: =2-B9+C9+D9 -> 1.272 | G9: 150 | H9: 0.55 | I9: 30 | J9: 2.6 | L9: 25 | M9: 2.5 | O9: 30 | P9: 2.86
A10: 6 | B10: 0.62 | C10: 0.003 | D10: 0 | E10: =2-B10+C10+D10 -> 1.383 | G10: 175 | H10: 0.47 | I10: 36 | J10: 2.65 | L10: 30 | M10: 2.58 | O10: 40 | P10: 3
A11: 8 | B11: 0.47 | C11: 0.006 | D11: 0 | E11: =2-B11+C11+D11 -> 1.536 | G11: 200 | H11: 0.38 | I11: 42 | J11: 2.72 | L11: 40 | M11: 2.68 | O11: 50 | P11: 3.08
A12: 10 | B12: 0.36 | C12: 0.012 | D12: 0 | E12: =2-B12+C12+D12 -> 1.652 | G12: 225 | H12: 0.3 | I12: 48 | J12: 2.8 | L12: 50 | M12: 2.8
A13: 12 | B13: 0.29 | C13: 0.02 | D13: 0 | E13: =2-B13+C13+D13 -> 1.73 | G13: 250 | H13: 0.22 | I13: 55 | J13: 2.9
A14: 15 | B14: 0.22 | C14: 0.03 | D14: 0 | E14: =2-B14+C14+D14 -> 1.81
A15: 20 | B15: 0.14 | C15: 0.055 | D15: 0.001 | E15: =2-B15+C15+D15 -> 1.916
A16: 25 | B16: 0.095 | C16: 0.09 | D16: 0.002 | E16: =2-B16+C16+D16 -> 1.997
A17: 30 | B17: 0.065 | C17: 0.13 | D17: 0.003 | E17: =2-B17+C17+D17 -> 2.068
A18: 40 | B18: 0.035 | C18: 0.2 | D18: 0.005 | E18: =2-B18+C18+D18 -> 2.17
A19: 50 | B19: 0.025 | C19: 0.27 | D19: 0.01 | E19: =2-B19+C19+D19 -> 2.255
A20: 60 | B20: 0.018 | C20: 0.34 | D20: 0.015 | E20: =2-B20+C20+D20 -> 2.337
A21: 80 | B21: 0.01 | C21: 0.45 | D21: 0.025 | E21: =2-B21+C21+D21 -> 2.465
A22: 100 | B22: 0.005 | C22: 0.53 | D22: 0.035 | E22: =2-B22+C22+D22 -> 2.56
A26: PUTTING - published scratch data used
A27: Shot Scope 0-hcp make %, fine bands (MyGolfSpy): 0-3 ft 98%, 3-6 ft 76%, 6-9 ft 49%, 9-12 ft 34%, 12-18 ft 19%, 18-24 ft 12%, 24-30 ft 7%, 30+ ft 4%.
A28: Shot Scope 0-hcp make %, broad bands (Shot Scope blog): 0-6 ft 92.8%, 6-12 ft 42.8%, 12-18 ft 25.1%, 18-24 ft 14.5%, 24-30 ft 8.3%, 30+ ft 4.3%. The two tables disagree at 12-18 ft (19% vs 25%); anchors use the midpoint.
A29: Three-putts: Arccos 1-5 index: 9.4% from 20-25 ft, 19.6% from 25+ ft; Arccos/Stagner scratch ~25% from 36-40 ft. Shot Scope scratch: 3% of holes (0.8/round), 4.6 ft left on average after a first putt from 30 ft (implies ~12-15% from 30 ft). Anchors sit between the two sources. Tour reference (PGA Tour/Broadie): 20 ft 2%, 30 ft 5%, 40 ft 10%, 60 ft 23%.
A30: Check: Shot Scope scratch = 29.9 putts/round, 1.85 putts per GIR. E(putts) here at 18 ft = 1.88, at 15 ft = 1.81.
A31: APPROACH - published scratch data used
A32: Shot Scope scratch proximity INCLUDING misses (Golf Monthly): 50-100 yds 26 ft, 100-150 yds 38 ft, 150-200 yds 54 ft, 200+ yds 92 ft; 17% of approaches inside 15 ft, 42% inside 30 ft. Scratch GIR overall 52-59% (two Shot Scope figures). Tour GIR by distance used for the shape of the curve.
A33: GIR, on-green proximity and miss distance were chosen so that GIR x on-green + (1-GIR) x miss reproduces those band averages: implied miss distances 53 / 59 / 70 / 111 ft, and overall GIR ~55% for a typical mix of approach lengths. The on-green proximity and GIR split is DERIVED, not published.
A34: E after a miss = short-game value for the typical miss (chip/pitch, some sand), rising with approach length.
A35: AROUND THE GREEN - published scratch data used
A36: Shot Scope scratch (MyGolfSpy short-game chart): up-and-down <25 yds 63%, 25-50 yds 32%, inside 50 yds overall 54%, sand save 37%, average proximity after the shot 11 ft, shots to finish from inside 50 yds 2.45. E ~ 3 - up-and-down% + ~0.03 (double chips and three-putts minus holed shots).
A37: TOUR comparison on 'Tour Ref': scratch sits ~+0.05 to +0.15 behind tour on putts, ~+0.1 around the green, and ~+0.2 to +0.3 on approaches, in line with Broadie's finding that approach play is the largest scratch-to-tour gap.
... A48: https://golfingfocus.com/what-percentage-of-putts-do-pros-make-tv-does-not-tell-the-story/ (PGA Tour make and three-putt by distance)

Sheet Baseline
A1: Scratch expected strokes to hole out, built from 'Scratch Data' and 'Inputs'. Yards for F/R/S/X, feet for G.
A2: Yards | B2: F | C2: R | D2: S | E2: X | H2: Feet | I2: G
A3: 5 | B3: =IF($A3<=50,(INDEX('Scratch Data'!$M$5:$M$12,MATCH($A3,'Scratch Data'!$L$5:$L$12,1))+($A3-INDEX('Scratch Data'!$L$5:$L$12,MATCH($A3,'Scratch Data'!$L$5:$L$12,1)))*(INDEX('Scratch Data'!$M$5:$M$12,MIN(MATCH($A3,'Scratch Data'!$L$5:$L$12,1)+1,ROWS('Scratch Data'!$L$5:$L$12)))-INDEX('Scratch Data'!$M$5:$M$12,MATCH($A3,'Scratch Data'!$L$5:$L$12,1)))/MAX(INDEX('Scratch Data'!$L$5:$L$12,MIN(MATCH($A3,'Scratch Data'!$L$5:$L$12,1)+1,ROWS('Scratch Data'!$L$5:$L$12)))-INDEX('Scratch Data'!$L$5:$L$12,MATCH($A3,'Scratch Data'!$L$5:$L$12,1)),0.0001)),IF($A3<=250,MIN((1+(INDEX('Scratch Data'!$H$5:$H$13,MATCH($A3,'Scratch Data'!$G$5:$G$13,1))+($A3-INDEX('Scratch Data'!$G$5:$G$13,MATCH($A3,'Scratch Data'!$G$5:$G$13,1)))*(INDEX('Scratch Data'!$H$5:$H$13,MIN(MATCH($A3,'Scratch Data'!$G$5:$G$13,1)+1,ROWS('Scratch Data'!$G$5:$G$13)))-INDEX('Scratch Data'!$H$5:$H$13,MATCH($A3,'Scratch Data'!$G$5:$G$13,1)))/MAX(INDEX('Scratch Data'!$G$5:$G$13,MIN(MATCH($A3,'Scratch Data'!$G$5:$G$13,1)+1,ROWS('Scratch Data'!$G$5:$G$13)))-INDEX('Scratch Data'!$G$5:$G$13,MATCH($A3,'Scratch Data'!$G$5:$G$13,1)),0.0001))*INDEX(Baseline!$I$3:$I$102,MIN(MAX(ROUND(Inputs!$B$11*(INDEX('Scratch Data'!$I$5:$I$13,MATCH($A3,'Scratch Data'!$G$5:$G$13,1))+($A3-INDEX('Scratch Data'!$G$5:$G$13,MATCH($A3,'Scratch Data'!$G$5:$G$13,1)))*(INDEX('Scratch Data'!$I$5:$I$13,MIN(MATCH($A3,'Scratch Data'!$G$5:$G$13,1)+1,ROWS('Scratch Data'!$G$5:$G$13)))-INDEX('Scratch Data'!$I$5:$I$13,MATCH($A3,'Scratch Data'!$G$5:$G$13,1)))/MAX(INDEX('Scratch Data'!$G$5:$G$13,MIN(MATCH($A3,'Scratch Data'!$G$5:$G$13,1)+1,ROWS('Scratch Data'!$G$5:$G$13)))-INDEX('Scratch Data'!$G$5:$G$13,MATCH($A3,'Scratch Data'!$G$5:$G$13,1)),0.0001)),0),1),100))+(1-(INDEX('Scratch Data'!$H$5:$H$13,MATCH($A3,'Scratch Data'!$G$5:$G$13,1))+($A3-INDEX('Scratch Data'!$G$5:$G$13,MATCH($A3,'Scratch Data'!$G$5:$G$13,1)))*(INDEX('Scratch Data'!$H$5:$H$13,MIN(MATCH($A3,'Scratch Data'!$G$5:$G$13,1)+1,ROWS('Scratch Data'!$G$5:$G$13)))-INDEX('Scratch Data'!$H$5:$H$13,MATCH($A3,'Scratch Data'!$G$5:$G$13,1)))/MAX(INDEX('Scratch Data'!$G$5:$G$13,MIN(MATCH($A3,'Scratch Data'!$G$5:$G$13,1)+1,ROWS('Scratch Data'!$G$5:$G$13)))-INDEX('Scratch Data'!$G$5:$G$13,MATCH($A3,'Scratch Data'!$G$5:$G$13,1)),0.0001)))*(INDEX('Scratch Data'!$J$5:$J$13,MATCH($A3,'Scratch Data'!$G$5:$G$13,1))+($A3-INDEX('Scratch Data'!$G$5:$G$13,MATCH($A3,'Scratch Data'!$G$5:$G$13,1)))*(INDEX('Scratch Data'!$J$5:$J$13,MIN(MATCH($A3,'Scratch Data'!$G$5:$G$13,1)+1,ROWS('Scratch Data'!$G$5:$G$13)))-INDEX('Scratch Data'!$J$5:$J$13,MATCH($A3,'Scratch Data'!$G$5:$G$13,1)))/MAX(INDEX('Scratch Data'!$G$5:$G$13,MIN(MATCH($A3,'Scratch Data'!$G$5:$G$13,1)+1,ROWS('Scratch Data'!$G$5:$G$13)))-INDEX('Scratch Data'!$G$5:$G$13,MATCH($A3,'Scratch Data'!$G$5:$G$13,1)),0.0001))),(1+Inputs!$B$19*INDEX(Baseline!$B$3:$B$122,MATCH(MIN(MAX(ROUND((MAX($A3-Inputs!$B$20,30))/5,0)*5,5),600),Baseline!$A$3:$A$122,0))+(1-Inputs!$B$19)*INDEX(Baseline!$C$3:$C$122,MATCH(MIN(MAX(ROUND((MAX($A3-Inputs!$B$20,30))/5,0)*5,5),600),Baseline!$A$3:$A$122,0)))),(1+Inputs!$B$19*INDEX(Baseline!$B$3:$B$122,MATCH(MIN(MAX(ROUND((MAX($A3-Inputs!$B$20,30))/5,0)*5,5),600),Baseline!$A$3:$A$122,0))+(1-Inputs!$B$19)*INDEX(Baseline!$C$3:$C$122,MATCH(MIN(MAX(ROUND((MAX($A3-Inputs!$B$20,30))/5,0)*5,5),600),Baseline!$A$3:$A$122,0))))) -> 2.18 | C3: =IF($A3<=50,$B3+Inputs!$B$18,IF($A3<=250,MIN((1+(INDEX('Scratch Data'!$H$5:$H$13,MATCH($A3,'Scratch Data'!$G$5:$G$13,1))+($A3-INDEX('Scratch Data'!$G$5:$G$13,MATCH($A3,'Scratch Data'!$G$5:$G$13,1)))*(INDEX('Scratch Data'!$H$5:$H$13,MIN(MATCH($A3,'Scratch Data'!$G$5:$G$13,1)+1,ROWS('Scratch Data'!$G$5:$G$13)))-INDEX('Scratch Data'!$H$5:$H$13,MATCH($A3,'Scratch Data'!$G$5:$G$13,1)))/MAX(INDEX('Scratch Data'!$G$5:$G$13,MIN(MATCH($A3,'Scratch Data'!$G$5:$G$13,1)+1,ROWS('Scratch Data'!$G$5:$G$13)))-INDEX('Scratch Data'!$G$5:$G$13,MATCH($A3,'Scratch Data'!$G$5:$G$13,1)),0.0001))*Inputs!$B$12*INDEX(Baseline!$I$3:$I$102,MIN(MAX(ROUND(Inputs!$B$11*(INDEX('Scratch Data'!$I$5:$I$13,MATCH($A3,'Scratch Data'!$G$5:$G$13,1))+($A3-INDEX('Scratch Data'!$G$5:$G$13,MATCH($A3,'Scratch Data'!$G$5:$G$13,1)))*(INDEX('Scratch Data'!$I$5:$I$13,MIN(MATCH($A3,'Scratch Data'!$G$5:$G$13,1)+1,ROWS('Scratch Data'!$G$5:$G$13)))-INDEX('Scratch Data'!$I$5:$I$13,MATCH($A3,'Scratch Data'!$G$5:$G$13,1)))/MAX(INDEX('Scratch Data'!$G$5:$G$13,MIN(MATCH($A3,'Scratch Data'!$G$5:$G$13,1)+1,ROWS('Scratch Data'!$G$5:$G$13)))-INDEX('Scratch Data'!$G$5:$G$13,MATCH($A3,'Scratch Data'!$G$5:$G$13,1)),0.0001))*Inputs!$B$13,0),1),100))+(1-(INDEX('Scratch Data'!$H$5:$H$13,MATCH($A3,'Scratch Data'!$G$5:$G$13,1))+($A3-INDEX('Scratch Data'!$G$5:$G$13,MATCH($A3,'Scratch Data'!$G$5:$G$13,1)))*(INDEX('Scratch Data'!$H$5:$H$13,MIN(MATCH($A3,'Scratch Data'!$G$5:$G$13,1)+1,ROWS('Scratch Data'!$G$5:$G$13)))-INDEX('Scratch Data'!$H$5:$H$13,MATCH($A3,'Scratch Data'!$G$5:$G$13,1)))/MAX(INDEX('Scratch Data'!$G$5:$G$13,MIN(MATCH($A3,'Scratch Data'!$G$5:$G$13,1)+1,ROWS('Scratch Data'!$G$5:$G$13)))-INDEX('Scratch Data'!$G$5:$G$13,MATCH($A3,'Scratch Data'!$G$5:$G$13,1)),0.0001))*Inputs!$B$12)*((INDEX('Scratch Data'!$J$5:$J$13,MATCH($A3,'Scratch Data'!$G$5:$G$13,1))+($A3-INDEX('Scratch Data'!$G$5:$G$13,MATCH($A3,'Scratch Data'!$G$5:$G$13,1)))*(INDEX('Scratch Data'!$J$5:$J$13,MIN(MATCH($A3,'Scratch Data'!$G$5:$G$13,1)+1,ROWS('Scratch Data'!$G$5:$G$13)))-INDEX('Scratch Data'!$J$5:$J$13,MATCH($A3,'Scratch Data'!$G$5:$G$13,1)))/MAX(INDEX('Scratch Data'!$G$5:$G$13,MIN(MATCH($A3,'Scratch Data'!$G$5:$G$13,1)+1,ROWS('Scratch Data'!$G$5:$G$13)))-INDEX('Scratch Data'!$G$5:$G$13,MATCH($A3,'Scratch Data'!$G$5:$G$13,1)),0.0001))+Inputs!$B$14)),(1+Inputs!$B$19*INDEX(Baseline!$B$3:$B$122,MATCH(MIN(MAX(ROUND((MAX($A3-Inputs!$B$21,30))/5,0)*5,5),600),Baseline!$A$3:$A$122,0))+(1-Inputs!$B$19)*INDEX(Baseline!$C$3:$C$122,MATCH(MIN(MAX(ROUND((MAX($A3-Inputs!$B$21,30))/5,0)*5,5),600),Baseline!$A$3:$A$122,0))+Inputs!$B$14)),(1+Inputs!$B$19*INDEX(Baseline!$B$3:$B$122,MATCH(MIN(MAX(ROUND((MAX($A3-Inputs!$B$21,30))/5,0)*5,5),600),Baseline!$A$3:$A$122,0))+(1-Inputs!$B$19)*INDEX(Baseline!$C$3:$C$122,MATCH(MIN(MAX(ROUND((MAX($A3-Inputs!$B$21,30))/5,0)*5,5),600),Baseline!$A$3:$A$122,0))+Inputs!$B$14))) -> 2.38 | D3: =IF($A3<=50,(INDEX('Scratch Data'!$P$5:$P$11,MATCH($A3,'Scratch Data'!$O$5:$O$11,1))+($A3-INDEX('Scratch Data'!$O$5:$O$11,MATCH($A3,'Scratch Data'!$O$5:$O$11,1)))*(INDEX('Scratch Data'!$P$5:$P$11,MIN(MATCH($A3,'Scratch Data'!$O$5:$O$11,1)+1,ROWS('Scratch Data'!$O$5:$O$11)))-INDEX('Scratch Data'!$P$5:$P$11,MATCH($A3,'Scratch Data'!$O$5:$O$11,1)))/MAX(INDEX('Scratch Data'!$O$5:$O$11,MIN(MATCH($A3,'Scratch Data'!$O$5:$O$11,1)+1,ROWS('Scratch Data'!$O$5:$O$11)))-INDEX('Scratch Data'!$O$5:$O$11,MATCH($A3,'Scratch Data'!$O$5:$O$11,1)),0.0001)),IF($A3<=250,MIN((1+(INDEX('Scratch Data'!$H$5:$H$13,MATCH($A3,'Scratch Data'!$G$5:$G$13,1))+($A3-INDEX('Scratch Data'!$G$5:$G$13,MATCH($A3,'Scratch Data'!$G$5:$G$13,1)))*(INDEX('Scratch Data'!$H$5:$H$13,MIN(MATCH($A3,'Scratch Data'!$G$5:$G$13,1)+1,ROWS('Scratch Data'!$G$5:$G$13)))-INDEX('Scratch Data'!$H$5:$H$13,MATCH($A3,'Scratch Data'!$G$5:$G$13,1)))/MAX(INDEX('Scratch Data'!$G$5:$G$13,MIN(MATCH($A3,'Scratch Data'!$G$5:$G$13,1)+1,ROWS('Scratch Data'!$G$5:$G$13)))-INDEX('Scratch Data'!$G$5:$G$13,MATCH($A3,'Scratch Data'!$G$5:$G$13,1)),0.0001))*Inputs!$B$15*INDEX(Baseline!$I$3:$I$102,MIN(MAX(ROUND(Inputs!$B$11*(INDEX('Scratch Data'!$I$5:$I$13,MATCH($A3,'Scratch Data'!$G$5:$G$13,1))+($A3-INDEX('Scratch Data'!$G$5:$G$13,MATCH($A3,'Scratch Data'!$G$5:$G$13,1)))*(INDEX('Scratch Data'!$I$5:$I$13,MIN(MATCH($A3,'Scratch Data'!$G$5:$G$13,1)+1,ROWS('Scratch Data'!$G$5:$G$13)))-INDEX('Scratch Data'!$I$5:$I$13,MATCH($A3,'Scratch Data'!$G$5:$G$13,1)))/MAX(INDEX('Scratch Data'!$G$5:$G$13,MIN(MATCH($A3,'Scratch Data'!$G$5:$G$13,1)+1,ROWS('Scratch Data'!$G$5:$G$13)))-INDEX('Scratch Data'!$G$5:$G$13,MATCH($A3,'Scratch Data'!$G$5:$G$13,1)),0.0001))*Inputs!$B$16,0),1),100))+(1-(INDEX('Scratch Data'!$H$5:$H$13,MATCH($A3,'Scratch Data'!$G$5:$G$13,1))+($A3-INDEX('Scratch Data'!$G$5:$G$13,MATCH($A3,'Scratch Data'!$G$5:$G$13,1)))*(INDEX('Scratch Data'!$H$5:$H$13,MIN(MATCH($A3,'Scratch Data'!$G$5:$G$13,1)+1,ROWS('Scratch Data'!$G$5:$G$13)))-INDEX('Scratch Data'!$H$5:$H$13,MATCH($A3,'Scratch Data'!$G$5:$G$13,1)))/MAX(INDEX('Scratch Data'!$G$5:$G$13,MIN(MATCH($A3,'Scratch Data'!$G$5:$G$13,1)+1,ROWS('Scratch Data'!$G$5:$G$13)))-INDEX('Scratch Data'!$G$5:$G$13,MATCH($A3,'Scratch Data'!$G$5:$G$13,1)),0.0001))*Inputs!$B$15)*((INDEX('Scratch Data'!$J$5:$J$13,MATCH($A3,'Scratch Data'!$G$5:$G$13,1))+($A3-INDEX('Scratch Data'!$G$5:$G$13,MATCH($A3,'Scratch Data'!$G$5:$G$13,1)))*(INDEX('Scratch Data'!$J$5:$J$13,MIN(MATCH($A3,'Scratch Data'!$G$5:$G$13,1)+1,ROWS('Scratch Data'!$G$5:$G$13)))-INDEX('Scratch Data'!$J$5:$J$13,MATCH($A3,'Scratch Data'!$G$5:$G$13,1)))/MAX(INDEX('Scratch Data'!$G$5:$G$13,MIN(MATCH($A3,'Scratch Data'!$G$5:$G$13,1)+1,ROWS('Scratch Data'!$G$5:$G$13)))-INDEX('Scratch Data'!$G$5:$G$13,MATCH($A3,'Scratch Data'!$G$5:$G$13,1)),0.0001))+Inputs!$B$17)),(1+Inputs!$B$19*INDEX(Baseline!$B$3:$B$122,MATCH(MIN(MAX(ROUND((MAX($A3-Inputs!$B$22,30))/5,0)*5,5),600),Baseline!$A$3:$A$122,0))+(1-Inputs!$B$19)*INDEX(Baseline!$C$3:$C$122,MATCH(MIN(MAX(ROUND((MAX($A3-Inputs!$B$22,30))/5,0)*5,5),600),Baseline!$A$3:$A$122,0))+Inputs!$B$17)),(1+Inputs!$B$19*INDEX(Baseline!$B$3:$B$122,MATCH(MIN(MAX(ROUND((MAX($A3-Inputs!$B$22,30))/5,0)*5,5),600),Baseline!$A$3:$A$122,0))+(1-Inputs!$B$19)*INDEX(Baseline!$C$3:$C$122,MATCH(MIN(MAX(ROUND((MAX($A3-Inputs!$B$22,30))/5,0)*5,5),600),Baseline!$A$3:$A$122,0))+Inputs!$B$17))) -> 2.55 | E3: =1+Inputs!$B$24+0.6*INDEX(Baseline!$B$3:$B$122,MATCH(MIN(MAX(ROUND((MAX($A3-Inputs!$B$23,15))/5,0)*5,5),600),Baseline!$A$3:$A$122,0))+0.4*INDEX(Baseline!$C$3:$C$122,MATCH(MIN(MAX(ROUND((MAX($A3-Inputs!$B$23,15))/5,0)*5,5),600),Baseline!$A$3:$A$122,0)) -> 3.56 | H3: 1 | I3: =(INDEX('Scratch Data'!$E$5:$E$22,MATCH($H3,'Scratch Data'!$A$5:$A$22,1))+($H3-INDEX('Scratch Data'!$A$5:$A$22,MATCH($H3,'Scratch Data'!$A$5:$A$22,1)))*(INDEX('Scratch Data'!$E$5:$E$22,MIN(MATCH($H3,'Scratch Data'!$A$5:$A$22,1)+1,ROWS('Scratch Data'!$A$5:$A$22)))-INDEX('Scratch Data'!$E$5:$E$22,MATCH($H3,'Scratch Data'!$A$5:$A$22,1)))/MAX(INDEX('Scratch Data'!$A$5:$A$22,MIN(MATCH($H3,'Scratch Data'!$A$5:$A$22,1)+1,ROWS('Scratch Data'!$A$5:$A$22)))-INDEX('Scratch Data'!$A$5:$A$22,MATCH($H3,'Scratch Data'!$A$5:$A$22,1)),0.0001)) -> 1
A4: 10 | B4: =IF($A4<=50,(INDEX('Scratch Data'!$M$5:$M$12,MATCH($A4,'Scratch Data'!$L$5:$L$12,1))+($A4-INDEX('Scratch Data'!$L$5:$L$12,MATCH($A4,'Scratch Data'!$L$5:$L$12,1)))*(INDEX('Scratch Data'!$M$5:$M$12,MIN(MATCH($A4,'Scratch Data'!$L$5:$L$12,1)+1,ROWS('Scratch Data'!$L$5:$L$12)))-INDEX('Scratch Data'!$M$5:$M$12,MATCH($A4,'Scratch Data'!$L$5:$L$12,1)))/MAX(INDEX('Scratch Data'!$L$5:$L$12,MIN(MATCH($A4,'Scratch Data'!$L$5:$L$12,1)+1,ROWS('Scratch Data'!$L$5:$L$12)))-INDEX('Scratch Data'!$L$5:$L$12,MATCH($A4,'Scratch Data'!$L$5:$L$12,1)),0.0001)),IF($A4<=250,MIN((1+(INDEX('Scratch Data'!$H$5:$H$13,MATCH($A4,'Scratch Data'!$G$5:$G$13,1))+($A4-INDEX('Scratch Data'!$G$5:$G$13,MATCH($A4,'Scratch Data'!$G$5:$G$13,1)))*(INDEX('Scratch Data'!$H$5:$H$13,MIN(MATCH($A4,'Scratch Data'!$G$5:$G$13,1)+1,ROWS('Scratch Data'!$G$5:$G$13)))-INDEX('Scratch Data'!$H$5:$H$13,MATCH($A4,'Scratch Data'!$G$5:$G$13,1)))/MAX(INDEX('Scratch Data'!$G$5:$G$13,MIN(MATCH($A4,'Scratch Data'!$G$5:$G$13,1)+1,ROWS('Scratch Data'!$G$5:$G$13)))-INDEX('Scratch Data'!$G$5:$G$13,MATCH($A4,'Scratch Data'!$G$5:$G$13,1)),0.0001))*INDEX(Baseline!$I$3:$I$102,MIN(MAX(ROUND(Inputs!$B$11*(INDEX('Scratch Data'!$I$5:$I$13,MATCH($A4,'Scratch Data'!$G$5:$G$13,1))+($A4-INDEX('Scratch Data'!$G$5:$G$13,MATCH($A4,'Scratch Data'!$G$5:$G$13,1)))*(INDEX('Scratch Data'!$I$5:$I$13,MIN(MATCH($A4,'Scratch Data'!$G$5:$G$13,1)+1,ROWS('Scratch Data'!$G$5:$G$13)))-INDEX('Scratch Data'!$I$5:$I$13,MATCH($A4,'Scratch Data'!$G$5:$G$13,1)))/MAX(INDEX('Scratch Data'!$G$5:$G$13,MIN(MATCH($A4,'Scratch Data'!$G$5:$G$13,1)+1,ROWS('Scratch Data'!$G$5:$G$13)))-INDEX('Scratch Data'!$G$5:$G$13,MATCH($A4,'Scratch Data'!$G$5:$G$13,1)),0.0001)),0),1),100))+(1-(INDEX('Scratch Data'!$H$5:$H$13,MATCH($A4,'Scratch Data'!$G$5:$G$13,1))+($A4-INDEX('Scratch Data'!$G$5:$G$13,MATCH($A4,'Scratch Data'!$G$5:$G$13,1)))*(INDEX('Scratch Data'!$H$5:$H$13,MIN(MATCH($A4,'Scratch Data'!$G$5:$G$13,1)+1,ROWS('Scratch Data'!$G$5:$G$13)))-INDEX('Scratch Data'!$H$5:$H$13,MATCH($A4,'Scratch Data'!$G$5:$G$13,1)))/MAX(INDEX('Scratch Data'!$G$5:$G$13,MIN(MATCH($A4,'Scratch Data'!$G$5:$G$13,1)+1,ROWS('Scratch Data'!$G$5:$G$13)))-INDEX('Scratch Data'!$G$5:$G$13,MATCH($A4,'Scratch Data'!$G$5:$G$13,1)),0.0001)))*(INDEX('Scratch Data'!$J$5:$J$13,MATCH($A4,'Scratch Data'!$G$5:$G$13,1))+($A4-INDEX('Scratch Data'!$G$5:$G$13,MATCH($A4,'Scratch Data'!$G$5:$G$13,1)))*(INDEX('Scratch Data'!$J$5:$J$13,MIN(MATCH($A4,'Scratch Data'!$G$5:$G$13,1)+1,ROWS('Scratch Data'!$G$5:$G$13)))-INDEX('Scratch Data'!$J$5:$J$13,MATCH($A4,'Scratch Data'!$G$5:$G$13,1)))/MAX(INDEX('Scratch Data'!$G$5:$G$13,MIN(MATCH($A4,'Scratch Data'!$G$5:$G$13,1)+1,ROWS('Scratch Data'!$G$5:$G$13)))-INDEX('Scratch Data'!$G$5:$G$13,MATCH($A4,'Scratch Data'!$G$5:$G$13,1)),0.0001))),(1+Inputs!$B$19*INDEX(Baseline!$B$3:$B$122,MATCH(MIN(MAX(ROUND((MAX($A4-Inputs!$B$20,30))/5,0)*5,5),600),Baseline!$A$3:$A$122,0))+(1-Inputs!$B$19)*INDEX(Baseline!$C$3:$C$122,MATCH(MIN(MAX(ROUND((MAX($A4-Inputs!$B$20,30))/5,0)*5,5),600),Baseline!$A$3:$A$122,0)))),(1+Inputs!$B$19*INDEX(Baseline!$B$3:$B$122,MATCH(MIN(MAX(ROUND((MAX($A4-Inputs!$B$20,30))/5,0)*5,5),600),Baseline!$A$3:$A$122,0))+(1-Inputs!$B$19)*INDEX(Baseline!$C$3:$C$122,MATCH(MIN(MAX(ROUND((MAX($A4-Inputs!$B$20,30))/5,0)*5,5),600),Baseline!$A$3:$A$122,0))))) -> 2.3 | C4: =IF($A4<=50,$B4+Inputs!$B$18,IF($A4<=250,MIN((1+(INDEX('Scratch Data'!$H$5:$H$13,MATCH($A4,'Scratch Data'!$G$5:$G$13,1))+($A4-INDEX('Scratch Data'!$G$5:$G$13,MATCH($A4,'Scratch Data'!$G$5:$G$13,1)))*(INDEX('Scratch Data'!$H$5:$H$13,MIN(MATCH($A4,'Scratch Data'!$G$5:$G$13,1)+1,ROWS('Scratch Data'!$G$5:$G$13)))-INDEX('Scratch Data'!$H$5:$H$13,MATCH($A4,'Scratch Data'!$G$5:$G$13,1)))/MAX(INDEX('Scratch Data'!$G$5:$G$13,MIN(MATCH($A4,'Scratch Data'!$G$5:$G$13,1)+1,ROWS('Scratch Data'!$G$5:$G$13)))-INDEX('Scratch Data'!$G$5:$G$13,MATCH($A4,'Scratch Data'!$G$5:$G$13,1)),0.0001))*Inputs!$B$12*INDEX(Baseline!$I$3:$I$102,MIN(MAX(ROUND(Inputs!$B$11*(INDEX('Scratch Data'!$I$5:$I$13,MATCH($A4,'Scratch Data'!$G$5:$G$13,1))+($A4-INDEX('Scratch Data'!$G$5:$G$13,MATCH($A4,'Scratch Data'!$G$5:$G$13,1)))*(INDEX('Scratch Data'!$I$5:$I$13,MIN(MATCH($A4,'Scratch Data'!$G$5:$G$13,1)+1,ROWS('Scratch Data'!$G$5:$G$13)))-INDEX('Scratch Data'!$I$5:$I$13,MATCH($A4,'Scratch Data'!$G$5:$G$13,1)))/MAX(INDEX('Scratch Data'!$G$5:$G$13,MIN(MATCH($A4,'Scratch Data'!$G$5:$G$13,1)+1,ROWS('Scratch Data'!$G$5:$G$13)))-INDEX('Scratch Data'!$G$5:$G$13,MATCH($A4,'Scratch Data'!$G$5:$G$13,1)),0.0001))*Inputs!$B$13,0),1),100))+(1-(INDEX('Scratch Data'!$H$5:$H$13,MATCH($A4,'Scratch Data'!$G$5:$G$13,1))+($A4-INDEX('Scratch Data'!$G$5:$G$13,MATCH($A4,'Scratch Data'!$G$5:$G$13,1)))*(INDEX('Scratch Data'!$H$5:$H$13,MIN(MATCH($A4,'Scratch Data'!$G$5:$G$13,1)+1,ROWS('Scratch Data'!$G$5:$G$13)))-INDEX('Scratch Data'!$H$5:$H$13,MATCH($A4,'Scratch Data'!$G$5:$G$13,1)))/MAX(INDEX('Scratch Data'!$G$5:$G$13,MIN(MATCH($A4,'Scratch Data'!$G$5:$G$13,1)+1,ROWS('Scratch Data'!$G$5:$G$13)))-INDEX('Scratch Data'!$G$5:$G$13,MATCH($A4,'Scratch Data'!$G$5:$G$13,1)),0.0001))*Inputs!$B$12)*((INDEX('Scratch Data'!$J$5:$J$13,MATCH($A4,'Scratch Data'!$G$5:$G$13,1))+($A4-INDEX('Scratch Data'!$G$5:$G$13,MATCH($A4,'Scratch Data'!$G$5:$G$13,1)))*(INDEX('Scratch Data'!$J$5:$J$13,MIN(MATCH($A4,'Scratch Data'!$G$5:$G$13,1)+1,ROWS('Scratch Data'!$G$5:$G$13)))-INDEX('Scratch Data'!$J$5:$J$13,MATCH($A4,'Scratch Data'!$G$5:$G$13,1)))/MAX(INDEX('Scratch Data'!$G$5:$G$13,MIN(MATCH($A4,'Scratch Data'!$G$5:$G$13,1)+1,ROWS('Scratch Data'!$G$5:$G$13)))-INDEX('Scratch Data'!$G$5:$G$13,MATCH($A4,'Scratch Data'!$G$5:$G$13,1)),0.0001))+Inputs!$B$14)),(1+Inputs!$B$19*INDEX(Baseline!$B$3:$B$122,MATCH(MIN(MAX(ROUND((MAX($A4-Inputs!$B$21,30))/5,0)*5,5),600),Baseline!$A$3:$A$122,0))+(1-Inputs!$B$19)*INDEX(Baseline!$C$3:$C$122,MATCH(MIN(MAX(ROUND((MAX($A4-Inputs!$B$21,30))/5,0)*5,5),600),Baseline!$A$3:$A$122,0))+Inputs!$B$14)),(1+Inputs!$B$19*INDEX(Baseline!$B$3:$B$122,MATCH(MIN(MAX(ROUND((MAX($A4-Inputs!$B$21,30))/5,0)*5,5),600),Baseline!$A$3:$A$122,0))+(1-Inputs!$B$19)*INDEX(Baseline!$C$3:$C$122,MATCH(MIN(MAX(ROUND((MAX($A4-Inputs!$B$21,30))/5,0)*5,5),600),Baseline!$A$3:$A$122,0))+Inputs!$B$14))) -> 2.5 | D4: =IF($A4<=50,(INDEX('Scratch Data'!$P$5:$P$11,MATCH($A4,'Scratch Data'!$O$5:$O$11,1))+($A4-INDEX('Scratch Data'!$O$5:$O$11,MATCH($A4,'Scratch Data'!$O$5:$O$11,1)))*(INDEX('Scratch Data'!$P$5:$P$11,MIN(MATCH($A4,'Scratch Data'!$O$5:$O$11,1)+1,ROWS('Scratch Data'!$O$5:$O$11)))-INDEX('Scratch Data'!$P$5:$P$11,MATCH($A4,'Scratch Data'!$O$5:$O$11,1)))/MAX(INDEX('Scratch Data'!$O$5:$O$11,MIN(MATCH($A4,'Scratch Data'!$O$5:$O$11,1)+1,ROWS('Scratch Data'!$O$5:$O$11)))-INDEX('Scratch Data'!$O$5:$O$11,MATCH($A4,'Scratch Data'!$O$5:$O$11,1)),0.0001)),IF($A4<=250,MIN((1+(INDEX('Scratch Data'!$H$5:$H$13,MATCH($A4,'Scratch Data'!$G$5:$G$13,1))+($A4-INDEX('Scratch Data'!$G$5:$G$13,MATCH($A4,'Scratch Data'!$G$5:$G$13,1)))*(INDEX('Scratch Data'!$H$5:$H$13,MIN(MATCH($A4,'Scratch Data'!$G$5:$G$13,1)+1,ROWS('Scratch Data'!$G$5:$G$13)))-INDEX('Scratch Data'!$H$5:$H$13,MATCH($A4,'Scratch Data'!$G$5:$G$13,1)))/MAX(INDEX('Scratch Data'!$G$5:$G$13,MIN(MATCH($A4,'Scratch Data'!$G$5:$G$13,1)+1,ROWS('Scratch Data'!$G$5:$G$13)))-INDEX('Scratch Data'!$G$5:$G$13,MATCH($A4,'Scratch Data'!$G$5:$G$13,1)),0.0001))*Inputs!$B$15*INDEX(Baseline!$I$3:$I$102,MIN(MAX(ROUND(Inputs!$B$11*(INDEX('Scratch Data'!$I$5:$I$13,MATCH($A4,'Scratch Data'!$G$5:$G$13,1))+($A4-INDEX('Scratch Data'!$G$5:$G$13,MATCH($A4,'Scratch Data'!$G$5:$G$13,1)))*(INDEX('Scratch Data'!$I$5:$I$13,MIN(MATCH($A4,'Scratch Data'!$G$5:$G$13,1)+1,ROWS('Scratch Data'!$G$5:$G$13)))-INDEX('Scratch Data'!$I$5:$I$13,MATCH($A4,'Scratch Data'!$G$5:$G$13,1)))/MAX(INDEX('Scratch Data'!$G$5:$G$13,MIN(MATCH($A4,'Scratch Data'!$G$5:$G$13,1)+1,ROWS('Scratch Data'!$G$5:$G$13)))-INDEX('Scratch Data'!$G$5:$G$13,MATCH($A4,'Scratch Data'!$G$5:$G$13,1)),0.0001))*Inputs!$B$16,0),1),100))+(1-(INDEX('Scratch Data'!$H$5:$H$13,MATCH($A4,'Scratch Data'!$G$5:$G$13,1))+($A4-INDEX('Scratch Data'!$G$5:$G$13,MATCH($A4,'Scratch Data'!$G$5:$G$13,1)))*(INDEX('Scratch Data'!$H$5:$H$13,MIN(MATCH($A4,'Scratch Data'!$G$5:$G$13,1)+1,ROWS('Scratch Data'!$G$5:$G$13)))-INDEX('Scratch Data'!$H$5:$H$13,MATCH($A4,'Scratch Data'!$G$5:$G$13,1)))/MAX(INDEX('Scratch Data'!$G$5:$G$13,MIN(MATCH($A4,'Scratch Data'!$G$5:$G$13,1)+1,ROWS('Scratch Data'!$G$5:$G$13)))-INDEX('Scratch Data'!$G$5:$G$13,MATCH($A4,'Scratch Data'!$G$5:$G$13,1)),0.0001))*Inputs!$B$15)*((INDEX('Scratch Data'!$J$5:$J$13,MATCH($A4,'Scratch Data'!$G$5:$G$13,1))+($A4-INDEX('Scratch Data'!$G$5:$G$13,MATCH($A4,'Scratch Data'!$G$5:$G$13,1)))*(INDEX('Scratch Data'!$J$5:$J$13,MIN(MATCH($A4,'Scratch Data'!$G$5:$G$13,1)+1,ROWS('Scratch Data'!$G$5:$G$13)))-INDEX('Scratch Data'!$J$5:$J$13,MATCH($A4,'Scratch Data'!$G$5:$G$13,1)))/MAX(INDEX('Scratch Data'!$G$5:$G$13,MIN(MATCH($A4,'Scratch Data'!$G$5:$G$13,1)+1,ROWS('Scratch Data'!$G$5:$G$13)))-INDEX('Scratch Data'!$G$5:$G$13,MATCH($A4,'Scratch Data'!$G$5:$G$13,1)),0.0001))+Inputs!$B$17)),(1+Inputs!$B$19*INDEX(Baseline!$B$3:$B$122,MATCH(MIN(MAX(ROUND((MAX($A4-Inputs!$B$22,30))/5,0)*5,5),600),Baseline!$A$3:$A$122,0))+(1-Inputs!$B$19)*INDEX(Baseline!$C$3:$C$122,MATCH(MIN(MAX(ROUND((MAX($A4-Inputs!$B$22,30))/5,0)*5,5),600),Baseline!$A$3:$A$122,0))+Inputs!$B$17)),(1+Inputs!$B$19*INDEX(Baseline!$B$3:$B$122,MATCH(MIN(MAX(ROUND((MAX($A4-Inputs!$B$22,30))/5,0)*5,5),600),Baseline!$A$3:$A$122,0))+(1-Inputs!$B$19)*INDEX(Baseline!$C$3:$C$122,MATCH(MIN(MAX(ROUND((MAX($A4-Inputs!$B$22,30))/5,0)*5,5),600),Baseline!$A$3:$A$122,0))+Inputs!$B$17))) -> 2.62 | E4: =1+Inputs!$B$24+0.6*INDEX(Baseline!$B$3:$B$122,MATCH(MIN(MAX(ROUND((MAX($A4-Inputs!$B$23,15))/5,0)*5,5),600),Baseline!$A$3:$A$122,0))+0.4*INDEX(Baseline!$C$3:$C$122,MATCH(MIN(MAX(ROUND((MAX($A4-Inputs!$B$23,15))/5,0)*5,5),600),Baseline!$A$3:$A$122,0)) -> 3.56 | H4: 2 | I4: =(INDEX('Scratch Data'!$E$5:$E$22,MATCH($H4,'Scratch Data'!$A$5:$A$22,1))+($H4-INDEX('Scratch Data'!$A$5:$A$22,MATCH($H4,'Scratch Data'!$A$5:$A$22,1)))*(INDEX('Scratch Data'!$E$5:$E$22,MIN(MATCH($H4,'Scratch Data'!$A$5:$A$22,1)+1,ROWS('Scratch Data'!$A$5:$A$22)))-INDEX('Scratch Data'!$E$5:$E$22,MATCH($H4,'Scratch Data'!$A$5:$A$22,1)))/MAX(INDEX('Scratch Data'!$A$5:$A$22,MIN(MATCH($H4,'Scratch Data'!$A$5:$A$22,1)+1,ROWS('Scratch Data'!$A$5:$A$22)))-INDEX('Scratch Data'!$A$5:$A$22,MATCH($H4,'Scratch Data'!$A$5:$A$22,1)),0.0001)) -> 1.01
A5: 15 | B5: =IF($A5<=50,(INDEX('Scratch Data'!$M$5:$M$12,MATCH($A5,'Scratch Data'!$L$5:$L$12,1))+($A5-INDEX('Scratch Data'!$L$5:$L$12,MATCH($A5,'Scratch Data'!$L$5:$L$12,1)))*(INDEX('Scratch Data'!$M$5:$M$12,MIN(MATCH($A5,'Scratch Data'!$L$5:$L$12,1)+1,ROWS('Scratch Data'!$L$5:$L$12)))-INDEX('Scratch Data'!$M$5:$M$12,MATCH($A5,'Scratch Data'!$L$5:$L$12,1)))/MAX(INDEX('Scratch Data'!$L$5:$L$12,MIN(MATCH($A5,'Scratch Data'!$L$5:$L$12,1)+1,ROWS('Scratch Data'!$L$5:$L$12)))-INDEX('Scratch Data'!$L$5:$L$12,MATCH($A5,'Scratch Data'!$L$5:$L$12,1)),0.0001)),IF($A5<=250,MIN((1+(INDEX('Scratch Data'!$H$5:$H$13,MATCH($A5,'Scratch Data'!$G$5:$G$13,1))+($A5-INDEX('Scratch Data'!$G$5:$G$13,MATCH($A5,'Scratch Data'!$G$5:$G$13,1)))*(INDEX('Scratch Data'!$H$5:$H$13,MIN(MATCH($A5,'Scratch Data'!$G$5:$G$13,1)+1,ROWS('Scratch Data'!$G$5:$G$13)))-INDEX('Scratch Data'!$H$5:$H$13,MATCH($A5,'Scratch Data'!$G$5:$G$13,1)))/MAX(INDEX('Scratch Data'!$G$5:$G$13,MIN(MATCH($A5,'Scratch Data'!$G$5:$G$13,1)+1,ROWS('Scratch Data'!$G$5:$G$13)))-INDEX('Scratch Data'!$G$5:$G$13,MATCH($A5,'Scratch Data'!$G$5:$G$13,1)),0.0001))*INDEX(Baseline!$I$3:$I$102,MIN(MAX(ROUND(Inputs!$B$11*(INDEX('Scratch Data'!$I$5:$I$13,MATCH($A5,'Scratch Data'!$G$5:$G$13,1))+($A5-INDEX('Scratch Data'!$G$5:$G$13,MATCH($A5,'Scratch Data'!$G$5:$G$13,1)))*(INDEX('Scratch Data'!$I$5:$I$13,MIN(MATCH($A5,'Scratch Data'!$G$5:$G$13,1)+1,ROWS('Scratch Data'!$G$5:$G$13)))-INDEX('Scratch Data'!$I$5:$I$13,MATCH($A5,'Scratch Data'!$G$5:$G$13,1)))/MAX(INDEX('Scratch Data'!$G$5:$G$13,MIN(MATCH($A5,'Scratch Data'!$G$5:$G$13,1)+1,ROWS('Scratch Data'!$G$5:$G$13)))-INDEX('Scratch Data'!$G$5:$G$13,MATCH($A5,'Scratch Data'!$G$5:$G$13,1)),0.0001)),0),1),100))+(1-(INDEX('Scratch Data'!$H$5:$H$13,MATCH($A5,'Scratch Data'!$G$5:$G$13,1))+($A5-INDEX('Scratch Data'!$G$5:$G$13,MATCH($A5,'Scratch Data'!$G$5:$G$13,1)))*(INDEX('Scratch Data'!$H$5:$H$13,MIN(MATCH($A5,'Scratch Data'!$G$5:$G$13,1)+1,ROWS('Scratch Data'!$G$5:$G$13)))-INDEX('Scratch Data'!$H$5:$H$13,MATCH($A5,'Scratch Data'!$G$5:$G$13,1)))/MAX(INDEX('Scratch Data'!$G$5:$G$13,MIN(MATCH($A5,'Scratch Data'!$G$5:$G$13,1)+1,ROWS('Scratch Data'!$G$5:$G$13)))-INDEX('Scratch Data'!$G$5:$G$13,MATCH($A5,'Scratch Data'!$G$5:$G$13,1)),0.0001)))*(INDEX('Scratch Data'!$J$5:$J$13,MATCH($A5,'Scratch Data'!$G$5:$G$13,1))+($A5-INDEX('Scratch Data'!$G$5:$G$13,MATCH($A5,'Scratch Data'!$G$5:$G$13,1)))*(INDEX('Scratch Data'!$J$5:$J$13,MIN(MATCH($A5,'Scratch Data'!$G$5:$G$13,1)+1,ROWS('Scratch Data'!$G$5:$G$13)))-INDEX('Scratch Data'!$J$5:$J$13,MATCH($A5,'Scratch Data'!$G$5:$G$13,1)))/MAX(INDEX('Scratch Data'!$G$5:$G$13,MIN(MATCH($A5,'Scratch Data'!$G$5:$G$13,1)+1,ROWS('Scratch Data'!$G$5:$G$13)))-INDEX('Scratch Data'!$G$5:$G$13,MATCH($A5,'Scratch Data'!$G$5:$G$13,1)),0.0001))),(1+Inputs!$B$19*INDEX(Baseline!$B$3:$B$122,MATCH(MIN(MAX(ROUND((MAX($A5-Inputs!$B$20,30))/5,0)*5,5),600),Baseline!$A$3:$A$122,0))+(1-Inputs!$B$19)*INDEX(Baseline!$C$3:$C$122,MATCH(MIN(MAX(ROUND((MAX($A5-Inputs!$B$20,30))/5,0)*5,5),600),Baseline!$A$3:$A$122,0)))),(1+Inputs!$B$19*INDEX(Baseline!$B$3:$B$122,MATCH(MIN(MAX(ROUND((MAX($A5-Inputs!$B$20,30))/5,0)*5,5),600),Baseline!$A$3:$A$122,0))+(1-Inputs!$B$19)*INDEX(Baseline!$C$3:$C$122,MATCH(MIN(MAX(ROUND((MAX($A5-Inputs!$B$20,30))/5,0)*5,5),600),Baseline!$A$3:$A$122,0))))) -> 2.38 | C5: =IF($A5<=50,$B5+Inputs!$B$18,IF($A5<=250,MIN((1+(INDEX('Scratch Data'!$H$5:$H$13,MATCH($A5,'Scratch Data'!$G$5:$G$13,1))+($A5-INDEX('Scratch Data'!$G$5:$G$13,MATCH($A5,'Scratch Data'!$G$5:$G$13,1)))*(INDEX('Scratch Data'!$H$5:$H$13,MIN(MATCH($A5,'Scratch Data'!$G$5:$G$13,1)+1,ROWS('Scratch Data'!$G$5:$G$13)))-INDEX('Scratch Data'!$H$5:$H$13,MATCH($A5,'Scratch Data'!$G$5:$G$13,1)))/MAX(INDEX('Scratch Data'!$G$5:$G$13,MIN(MATCH($A5,'Scratch Data'!$G$5:$G$13,1)+1,ROWS('Scratch Data'!$G$5:$G$13)))-INDEX('Scratch Data'!$G$5:$G$13,MATCH($A5,'Scratch Data'!$G$5:$G$13,1)),0.0001))*Inputs!$B$12*INDEX(Baseline!$I$3:$I$102,MIN(MAX(ROUND(Inputs!$B$11*(INDEX('Scratch Data'!$I$5:$I$13,MATCH($A5,'Scratch Data'!$G$5:$G$13,1))+($A5-INDEX('Scratch Data'!$G$5:$G$13,MATCH($A5,'Scratch Data'!$G$5:$G$13,1)))*(INDEX('Scratch Data'!$I$5:$I$13,MIN(MATCH($A5,'Scratch Data'!$G$5:$G$13,1)+1,ROWS('Scratch Data'!$G$5:$G$13)))-INDEX('Scratch Data'!$I$5:$I$13,MATCH($A5,'Scratch Data'!$G$5:$G$13,1)))/MAX(INDEX('Scratch Data'!$G$5:$G$13,MIN(MATCH($A5,'Scratch Data'!$G$5:$G$13,1)+1,ROWS('Scratch Data'!$G$5:$G$13)))-INDEX('Scratch Data'!$G$5:$G$13,MATCH($A5,'Scratch Data'!$G$5:$G$13,1)),0.0001))*Inputs!$B$13,0),1),100))+(1-(INDEX('Scratch Data'!$H$5:$H$13,MATCH($A5,'Scratch Data'!$G$5:$G$13,1))+($A5-INDEX('Scratch Data'!$G$5:$G$13,MATCH($A5,'Scratch Data'!$G$5:$G$13,1)))*(INDEX('Scratch Data'!$H$5:$H$13,MIN(MATCH($A5,'Scratch Data'!$G$5:$G$13,1)+1,ROWS('Scratch Data'!$G$5:$G$13)))-INDEX('Scratch Data'!$H$5:$H$13,MATCH($A5,'Scratch Data'!$G$5:$G$13,1)))/MAX(INDEX('Scratch Data'!$G$5:$G$13,MIN(MATCH($A5,'Scratch Data'!$G$5:$G$13,1)+1,ROWS('Scratch Data'!$G$5:$G$13)))-INDEX('Scratch Data'!$G$5:$G$13,MATCH($A5,'Scratch Data'!$G$5:$G$13,1)),0.0001))*Inputs!$B$12)*((INDEX('Scratch Data'!$J$5:$J$13,MATCH($A5,'Scratch Data'!$G$5:$G$13,1))+($A5-INDEX('Scratch Data'!$G$5:$G$13,MATCH($A5,'Scratch Data'!$G$5:$G$13,1)))*(INDEX('Scratch Data'!$J$5:$J$13,MIN(MATCH($A5,'Scratch Data'!$G$5:$G$13,1)+1,ROWS('Scratch Data'!$G$5:$G$13)))-INDEX('Scratch Data'!$J$5:$J$13,MATCH($A5,'Scratch Data'!$G$5:$G$13,1)))/MAX(INDEX('Scratch Data'!$G$5:$G$13,MIN(MATCH($A5,'Scratch Data'!$G$5:$G$13,1)+1,ROWS('Scratch Data'!$G$5:$G$13)))-INDEX('Scratch Data'!$G$5:$G$13,MATCH($A5,'Scratch Data'!$G$5:$G$13,1)),0.0001))+Inputs!$B$14)),(1+Inputs!$B$19*INDEX(Baseline!$B$3:$B$122,MATCH(MIN(MAX(ROUND((MAX($A5-Inputs!$B$21,30))/5,0)*5,5),600),Baseline!$A$3:$A$122,0))+(1-Inputs!$B$19)*INDEX(Baseline!$C$3:$C$122,MATCH(MIN(MAX(ROUND((MAX($A5-Inputs!$B$21,30))/5,0)*5,5),600),Baseline!$A$3:$A$122,0))+Inputs!$B$14)),(1+Inputs!$B$19*INDEX(Baseline!$B$3:$B$122,MATCH(MIN(MAX(ROUND((MAX($A5-Inputs!$B$21,30))/5,0)*5,5),600),Baseline!$A$3:$A$122,0))+(1-Inputs!$B$19)*INDEX(Baseline!$C$3:$C$122,MATCH(MIN(MAX(ROUND((MAX($A5-Inputs!$B$21,30))/5,0)*5,5),600),Baseline!$A$3:$A$122,0))+Inputs!$B$14))) -> 2.58 | D5: =IF($A5<=50,(INDEX('Scratch Data'!$P$5:$P$11,MATCH($A5,'Scratch Data'!$O$5:$O$11,1))+($A5-INDEX('Scratch Data'!$O$5:$O$11,MATCH($A5,'Scratch Data'!$O$5:$O$11,1)))*(INDEX('Scratch Data'!$P$5:$P$11,MIN(MATCH($A5,'Scratch Data'!$O$5:$O$11,1)+1,ROWS('Scratch Data'!$O$5:$O$11)))-INDEX('Scratch Data'!$P$5:$P$11,MATCH($A5,'Scratch Data'!$O$5:$O$11,1)))/MAX(INDEX('Scratch Data'!$O$5:$O$11,MIN(MATCH($A5,'Scratch Data'!$O$5:$O$11,1)+1,ROWS('Scratch Data'!$O$5:$O$11)))-INDEX('Scratch Data'!$O$5:$O$11,MATCH($A5,'Scratch Data'!$O$5:$O$11,1)),0.0001)),IF($A5<=250,MIN((1+(INDEX('Scratch Data'!$H$5:$H$13,MATCH($A5,'Scratch Data'!$G$5:$G$13,1))+($A5-INDEX('Scratch Data'!$G$5:$G$13,MATCH($A5,'Scratch Data'!$G$5:$G$13,1)))*(INDEX('Scratch Data'!$H$5:$H$13,MIN(MATCH($A5,'Scratch Data'!$G$5:$G$13,1)+1,ROWS('Scratch Data'!$G$5:$G$13)))-INDEX('Scratch Data'!$H$5:$H$13,MATCH($A5,'Scratch Data'!$G$5:$G$13,1)))/MAX(INDEX('Scratch Data'!$G$5:$G$13,MIN(MATCH($A5,'Scratch Data'!$G$5:$G$13,1)+1,ROWS('Scratch Data'!$G$5:$G$13)))-INDEX('Scratch Data'!$G$5:$G$13,MATCH($A5,'Scratch Data'!$G$5:$G$13,1)),0.0001))*Inputs!$B$15*INDEX(Baseline!$I$3:$I$102,MIN(MAX(ROUND(Inputs!$B$11*(INDEX('Scratch Data'!$I$5:$I$13,MATCH($A5,'Scratch Data'!$G$5:$G$13,1))+($A5-INDEX('Scratch Data'!$G$5:$G$13,MATCH($A5,'Scratch Data'!$G$5:$G$13,1)))*(INDEX('Scratch Data'!$I$5:$I$13,MIN(MATCH($A5,'Scratch Data'!$G$5:$G$13,1)+1,ROWS('Scratch Data'!$G$5:$G$13)))-INDEX('Scratch Data'!$I$5:$I$13,MATCH($A5,'Scratch Data'!$G$5:$G$13,1)))/MAX(INDEX('Scratch Data'!$G$5:$G$13,MIN(MATCH($A5,'Scratch Data'!$G$5:$G$13,1)+1,ROWS('Scratch Data'!$G$5:$G$13)))-INDEX('Scratch Data'!$G$5:$G$13,MATCH($A5,'Scratch Data'!$G$5:$G$13,1)),0.0001))*Inputs!$B$16,0),1),100))+(1-(INDEX('Scratch Data'!$H$5:$H$13,MATCH($A5,'Scratch Data'!$G$5:$G$13,1))+($A5-INDEX('Scratch Data'!$G$5:$G$13,MATCH($A5,'Scratch Data'!$G$5:$G$13,1)))*(INDEX('Scratch Data'!$H$5:$H$13,MIN(MATCH($A5,'Scratch Data'!$G$5:$G$13,1)+1,ROWS('Scratch Data'!$G$5:$G$13)))-INDEX('Scratch Data'!$H$5:$H$13,MATCH($A5,'Scratch Data'!$G$5:$G$13,1)))/MAX(INDEX('Scratch Data'!$G$5:$G$13,MIN(MATCH($A5,'Scratch Data'!$G$5:$G$13,1)+1,ROWS('Scratch Data'!$G$5:$G$13)))-INDEX('Scratch Data'!$G$5:$G$13,MATCH($A5,'Scratch Data'!$G$5:$G$13,1)),0.0001))*Inputs!$B$15)*((INDEX('Scratch Data'!$J$5:$J$13,MATCH($A5,'Scratch Data'!$G$5:$G$13,1))+($A5-INDEX('Scratch Data'!$G$5:$G$13,MATCH($A5,'Scratch Data'!$G$5:$G$13,1)))*(INDEX('Scratch Data'!$J$5:$J$13,MIN(MATCH($A5,'Scratch Data'!$G$5:$G$13,1)+1,ROWS('Scratch Data'!$G$5:$G$13)))-INDEX('Scratch Data'!$J$5:$J$13,MATCH($A5,'Scratch Data'!$G$5:$G$13,1)))/MAX(INDEX('Scratch Data'!$G$5:$G$13,MIN(MATCH($A5,'Scratch Data'!$G$5:$G$13,1)+1,ROWS('Scratch Data'!$G$5:$G$13)))-INDEX('Scratch Data'!$G$5:$G$13,MATCH($A5,'Scratch Data'!$G$5:$G$13,1)),0.0001))+Inputs!$B$17)),(1+Inputs!$B$19*INDEX(Baseline!$B$3:$B$122,MATCH(MIN(MAX(ROUND((MAX($A5-Inputs!$B$22,30))/5,0)*5,5),600),Baseline!$A$3:$A$122,0))+(1-Inputs!$B$19)*INDEX(Baseline!$C$3:$C$122,MATCH(MIN(MAX(ROUND((MAX($A5-Inputs!$B$22,30))/5,0)*5,5),600),Baseline!$A$3:$A$122,0))+Inputs!$B$17)),(1+Inputs!$B$19*INDEX(Baseline!$B$3:$B$122,MATCH(MIN(MAX(ROUND((MAX($A5-Inputs!$B$22,30))/5,0)*5,5),600),Baseline!$A$3:$A$122,0))+(1-Inputs!$B$19)*INDEX(Baseline!$C$3:$C$122,MATCH(MIN(MAX(ROUND((MAX($A5-Inputs!$B$22,30))/5,0)*5,5),600),Baseline!$A$3:$A$122,0))+Inputs!$B$17))) -> 2.68 | E5: =1+Inputs!$B$24+0.6*INDEX(Baseline!$B$3:$B$122,MATCH(MIN(MAX(ROUND((MAX($A5-Inputs!$B$23,15))/5,0)*5,5),600),Baseline!$A$3:$A$122,0))+0.4*INDEX(Baseline!$C$3:$C$122,MATCH(MIN(MAX(ROUND((MAX($A5-Inputs!$B$23,15))/5,0)*5,5),600),Baseline!$A$3:$A$122,0)) -> 3.56 | H5: 3 | I5: =(INDEX('Scratch Data'!$E$5:$E$22,MATCH($H5,'Scratch Data'!$A$5:$A$22,1))+($H5-INDEX('Scratch Data'!$A$5:$A$22,MATCH($H5,'Scratch Data'!$A$5:$A$22,1)))*(INDEX('Scratch Data'!$E$5:$E$22,MIN(MATCH($H5,'Scratch Data'!$A$5:$A$22,1)+1,ROWS('Scratch Data'!$A$5:$A$22)))-INDEX('Scratch Data'!$E$5:$E$22,MATCH($H5,'Scratch Data'!$A$5:$A$22,1)))/MAX(INDEX('Scratch Data'!$A$5:$A$22,MIN(MATCH($H5,'Scratch Data'!$A$5:$A$22,1)+1,ROWS('Scratch Data'!$A$5:$A$22)))-INDEX('Scratch Data'!$A$5:$A$22,MATCH($H5,'Scratch Data'!$A$5:$A$22,1)),0.0001)) -> 1.06
A6: 20 | B6: =IF($A6<=50,(INDEX('Scratch Data'!$M$5:$M$12,MATCH($A6,'Scratch Data'!$L$5:$L$12,1))+($A6-INDEX('Scratch Data'!$L$5:$L$12,MATCH($A6,'Scratch Data'!$L$5:$L$12,1)))*(INDEX('Scratch Data'!$M$5:$M$12,MIN(MATCH($A6,'Scratch Data'!$L$5:$L$12,1)+1,ROWS('Scratch Data'!$L$5:$L$12)))-INDEX('Scratch Data'!$M$5:$M$12,MATCH($A6,'Scratch Data'!$L$5:$L$12,1)))/MAX(INDEX('Scratch Data'!$L$5:$L$12,MIN(MATCH($A6,'Scratch Data'!$L$5:$L$12,1)+1,ROWS('Scratch Data'!$L$5:$L$12)))-INDEX('Scratch Data'!$L$5:$L$12,MATCH($A6,'Scratch Data'!$L$5:$L$12,1)),0.0001)),IF($A6<=250,MIN((1+(INDEX('Scratch Data'!$H$5:$H$13,MATCH($A6,'Scratch Data'!$G$5:$G$13,1))+($A6-INDEX('Scratch Data'!$G$5:$G$13,MATCH($A6,'Scratch Data'!$G$5:$G$13,1)))*(INDEX('Scratch Data'!$H$5:$H$13,MIN(MATCH($A6,'Scratch Data'!$G$5:$G$13,1)+1,ROWS('Scratch Data'!$G$5:$G$13)))-INDEX('Scratch Data'!$H$5:$H$13,MATCH($A6,'Scratch Data'!$G$5:$G$13,1)))/MAX(INDEX('Scratch Data'!$G$5:$G$13,MIN(MATCH($A6,'Scratch Data'!$G$5:$G$13,1)+1,ROWS('Scratch Data'!$G$5:$G$13)))-INDEX('Scratch Data'!$G$5:$G$13,MATCH($A6,'Scratch Data'!$G$5:$G$13,1)),0.0001))*INDEX(Baseline!$I$3:$I$102,MIN(MAX(ROUND(Inputs!$B$11*(INDEX('Scratch Data'!$I$5:$I$13,MATCH($A6,'Scratch Data'!$G$5:$G$13,1))+($A6-INDEX('Scratch Data'!$G$5:$G$13,MATCH($A6,'Scratch Data'!$G$5:$G$13,1)))*(INDEX('Scratch Data'!$I$5:$I$13,MIN(MATCH($A6,'Scratch Data'!$G$5:$G$13,1)+1,ROWS('Scratch Data'!$G$5:$G$13)))-INDEX('Scratch Data'!$I$5:$I$13,MATCH($A6,'Scratch Data'!$G$5:$G$13,1)))/MAX(INDEX('Scratch Data'!$G$5:$G$13,MIN(MATCH($A6,'Scratch Data'!$G$5:$G$13,1)+1,ROWS('Scratch Data'!$G$5:$G$13)))-INDEX('Scratch Data'!$G$5:$G$13,MATCH($A6,'Scratch Data'!$G$5:$G$13,1)),0.0001)),0),1),100))+(1-(INDEX('Scratch Data'!$H$5:$H$13,MATCH($A6,'Scratch Data'!$G$5:$G$13,1))+($A6-INDEX('Scratch Data'!$G$5:$G$13,MATCH($A6,'Scratch Data'!$G$5:$G$13,1)))*(INDEX('Scratch Data'!$H$5:$H$13,MIN(MATCH($A6,'Scratch Data'!$G$5:$G$13,1)+1,ROWS('Scratch Data'!$G$5:$G$13)))-INDEX('Scratch Data'!$H$5:$H$13,MATCH($A6,'Scratch Data'!$G$5:$G$13,1)))/MAX(INDEX('Scratch Data'!$G$5:$G$13,MIN(MATCH($A6,'Scratch Data'!$G$5:$G$13,1)+1,ROWS('Scratch Data'!$G$5:$G$13)))-INDEX('Scratch Data'!$G$5:$G$13,MATCH($A6,'Scratch Data'!$G$5:$G$13,1)),0.0001)))*(INDEX('Scratch Data'!$J$5:$J$13,MATCH($A6,'Scratch Data'!$G$5:$G$13,1))+($A6-INDEX('Scratch Data'!$G$5:$G$13,MATCH($A6,'Scratch Data'!$G$5:$G$13,1)))*(INDEX('Scratch Data'!$J$5:$J$13,MIN(MATCH($A6,'Scratch Data'!$G$5:$G$13,1)+1,ROWS('Scratch Data'!$G$5:$G$13)))-INDEX('Scratch Data'!$J$5:$J$13,MATCH($A6,'Scratch Data'!$G$5:$G$13,1)))/MAX(INDEX('Scratch Data'!$G$5:$G$13,MIN(MATCH($A6,'Scratch Data'!$G$5:$G$13,1)+1,ROWS('Scratch Data'!$G$5:$G$13)))-INDEX('Scratch Data'!$G$5:$G$13,MATCH($A6,'Scratch Data'!$G$5:$G$13,1)),0.0001))),(1+Inputs!$B$19*INDEX(Baseline!$B$3:$B$122,MATCH(MIN(MAX(ROUND((MAX($A6-Inputs!$B$20,30))/5,0)*5,5),600),Baseline!$A$3:$A$122,0))+(1-Inputs!$B$19)*INDEX(Baseline!$C$3:$C$122,MATCH(MIN(MAX(ROUND((MAX($A6-Inputs!$B$20,30))/5,0)*5,5),600),Baseline!$A$3:$A$122,0)))),(1+Inputs!$B$19*INDEX(Baseline!$B$3:$B$122,MATCH(MIN(MAX(ROUND((MAX($A6-Inputs!$B$20,30))/5,0)*5,5),600),Baseline!$A$3:$A$122,0))+(1-Inputs!$B$19)*INDEX(Baseline!$C$3:$C$122,MATCH(MIN(MAX(ROUND((MAX($A6-Inputs!$B$20,30))/5,0)*5,5),600),Baseline!$A$3:$A$122,0))))) -> 2.44 | C6: =IF($A6<=50,$B6+Inputs!$B$18,IF($A6<=250,MIN((1+(INDEX('Scratch Data'!$H$5:$H$13,MATCH($A6,'Scratch Data'!$G$5:$G$13,1))+($A6-INDEX('Scratch Data'!$G$5:$G$13,MATCH($A6,'Scratch Data'!$G$5:$G$13,1)))*(INDEX('Scratch Data'!$H$5:$H$13,MIN(MATCH($A6,'Scratch Data'!$G$5:$G$13,1)+1,ROWS('Scratch Data'!$G$5:$G$13)))-INDEX('Scratch Data'!$H$5:$H$13,MATCH($A6,'Scratch Data'!$G$5:$G$13,1)))/MAX(INDEX('Scratch Data'!$G$5:$G$13,MIN(MATCH($A6,'Scratch Data'!$G$5:$G$13,1)+1,ROWS('Scratch Data'!$G$5:$G$13)))-INDEX('Scratch Data'!$G$5:$G$13,MATCH($A6,'Scratch Data'!$G$5:$G$13,1)),0.0001))*Inputs!$B$12*INDEX(Baseline!$I$3:$I$102,MIN(MAX(ROUND(Inputs!$B$11*(INDEX('Scratch Data'!$I$5:$I$13,MATCH($A6,'Scratch Data'!$G$5:$G$13,1))+($A6-INDEX('Scratch Data'!$G$5:$G$13,MATCH($A6,'Scratch Data'!$G$5:$G$13,1)))*(INDEX('Scratch Data'!$I$5:$I$13,MIN(MATCH($A6,'Scratch Data'!$G$5:$G$13,1)+1,ROWS('Scratch Data'!$G$5:$G$13)))-INDEX('Scratch Data'!$I$5:$I$13,MATCH($A6,'Scratch Data'!$G$5:$G$13,1)))/MAX(INDEX('Scratch Data'!$G$5:$G$13,MIN(MATCH($A6,'Scratch Data'!$G$5:$G$13,1)+1,ROWS('Scratch Data'!$G$5:$G$13)))-INDEX('Scratch Data'!$G$5:$G$13,MATCH($A6,'Scratch Data'!$G$5:$G$13,1)),0.0001))*Inputs!$B$13,0),1),100))+(1-(INDEX('Scratch Data'!$H$5:$H$13,MATCH($A6,'Scratch Data'!$G$5:$G$13,1))+($A6-INDEX('Scratch Data'!$G$5:$G$13,MATCH($A6,'Scratch Data'!$G$5:$G$13,1)))*(INDEX('Scratch Data'!$H$5:$H$13,MIN(MATCH($A6,'Scratch Data'!$G$5:$G$13,1)+1,ROWS('Scratch Data'!$G$5:$G$13)))-INDEX('Scratch Data'!$H$5:$H$13,MATCH($A6,'Scratch Data'!$G$5:$G$13,1)))/MAX(INDEX('Scratch Data'!$G$5:$G$13,MIN(MATCH($A6,'Scratch Data'!$G$5:$G$13,1)+1,ROWS('Scratch Data'!$G$5:$G$13)))-INDEX('Scratch Data'!$G$5:$G$13,MATCH($A6,'Scratch Data'!$G$5:$G$13,1)),0.0001))*Inputs!$B$12)*((INDEX('Scratch Data'!$J$5:$J$13,MATCH($A6,'Scratch Data'!$G$5:$G$13,1))+($A6-INDEX('Scratch Data'!$G$5:$G$13,MATCH($A6,'Scratch Data'!$G$5:$G$13,1)))*(INDEX('Scratch Data'!$J$5:$J$13,MIN(MATCH($A6,'Scratch Data'!$G$5:$G$13,1)+1,ROWS('Scratch Data'!$G$5:$G$13)))-INDEX('Scratch Data'!$J$5:$J$13,MATCH($A6,'Scratch Data'!$G$5:$G$13,1)))/MAX(INDEX('Scratch Data'!$G$5:$G$13,MIN(MATCH($A6,'Scratch Data'!$G$5:$G$13,1)+1,ROWS('Scratch Data'!$G$5:$G$13)))-INDEX('Scratch Data'!$G$5:$G$13,MATCH($A6,'Scratch Data'!$G$5:$G$13,1)),0.0001))+Inputs!$B$14)),(1+Inputs!$B$19*INDEX(Baseline!$B$3:$B$122,MATCH(MIN(MAX(ROUND((MAX($A6-Inputs!$B$21,30))/5,0)*5,5),600),Baseline!$A$3:$A$122,0))+(1-Inputs!$B$19)*INDEX(Baseline!$C$3:$C$122,MATCH(MIN(MAX(ROUND((MAX($A6-Inputs!$B$21,30))/5,0)*5,5),600),Baseline!$A$3:$A$122,0))+Inputs!$B$14)),(1+Inputs!$B$19*INDEX(Baseline!$B$3:$B$122,MATCH(MIN(MAX(ROUND((MAX($A6-Inputs!$B$21,30))/5,0)*5,5),600),Baseline!$A$3:$A$122,0))+(1-Inputs!$B$19)*INDEX(Baseline!$C$3:$C$122,MATCH(MIN(MAX(ROUND((MAX($A6-Inputs!$B$21,30))/5,0)*5,5),600),Baseline!$A$3:$A$122,0))+Inputs!$B$14))) -> 2.64 | D6: =IF($A6<=50,(INDEX('Scratch Data'!$P$5:$P$11,MATCH($A6,'Scratch Data'!$O$5:$O$11,1))+($A6-INDEX('Scratch Data'!$O$5:$O$11,MATCH($A6,'Scratch Data'!$O$5:$O$11,1)))*(INDEX('Scratch Data'!$P$5:$P$11,MIN(MATCH($A6,'Scratch Data'!$O$5:$O$11,1)+1,ROWS('Scratch Data'!$O$5:$O$11)))-INDEX('Scratch Data'!$P$5:$P$11,MATCH($A6,'Scratch Data'!$O$5:$O$11,1)))/MAX(INDEX('Scratch Data'!$O$5:$O$11,MIN(MATCH($A6,'Scratch Data'!$O$5:$O$11,1)+1,ROWS('Scratch Data'!$O$5:$O$11)))-INDEX('Scratch Data'!$O$5:$O$11,MATCH($A6,'Scratch Data'!$O$5:$O$11,1)),0.0001)),IF($A6<=250,MIN((1+(INDEX('Scratch Data'!$H$5:$H$13,MATCH($A6,'Scratch Data'!$G$5:$G$13,1))+($A6-INDEX('Scratch Data'!$G$5:$G$13,MATCH($A6,'Scratch Data'!$G$5:$G$13,1)))*(INDEX('Scratch Data'!$H$5:$H$13,MIN(MATCH($A6,'Scratch Data'!$G$5:$G$13,1)+1,ROWS('Scratch Data'!$G$5:$G$13)))-INDEX('Scratch Data'!$H$5:$H$13,MATCH($A6,'Scratch Data'!$G$5:$G$13,1)))/MAX(INDEX('Scratch Data'!$G$5:$G$13,MIN(MATCH($A6,'Scratch Data'!$G$5:$G$13,1)+1,ROWS('Scratch Data'!$G$5:$G$13)))-INDEX('Scratch Data'!$G$5:$G$13,MATCH($A6,'Scratch Data'!$G$5:$G$13,1)),0.0001))*Inputs!$B$15*INDEX(Baseline!$I$3:$I$102,MIN(MAX(ROUND(Inputs!$B$11*(INDEX('Scratch Data'!$I$5:$I$13,MATCH($A6,'Scratch Data'!$G$5:$G$13,1))+($A6-INDEX('Scratch Data'!$G$5:$G$13,MATCH($A6,'Scratch Data'!$G$5:$G$13,1)))*(INDEX('Scratch Data'!$I$5:$I$13,MIN(MATCH($A6,'Scratch Data'!$G$5:$G$13,1)+1,ROWS('Scratch Data'!$G$5:$G$13)))-INDEX('Scratch Data'!$I$5:$I$13,MATCH($A6,'Scratch Data'!$G$5:$G$13,1)))/MAX(INDEX('Scratch Data'!$G$5:$G$13,MIN(MATCH($A6,'Scratch Data'!$G$5:$G$13,1)+1,ROWS('Scratch Data'!$G$5:$G$13)))-INDEX('Scratch Data'!$G$5:$G$13,MATCH($A6,'Scratch Data'!$G$5:$G$13,1)),0.0001))*Inputs!$B$16,0),1),100))+(1-(INDEX('Scratch Data'!$H$5:$H$13,MATCH($A6,'Scratch Data'!$G$5:$G$13,1))+($A6-INDEX('Scratch Data'!$G$5:$G$13,MATCH($A6,'Scratch Data'!$G$5:$G$13,1)))*(INDEX('Scratch Data'!$H$5:$H$13,MIN(MATCH($A6,'Scratch Data'!$G$5:$G$13,1)+1,ROWS('Scratch Data'!$G$5:$G$13)))-INDEX('Scratch Data'!$H$5:$H$13,MATCH($A6,'Scratch Data'!$G$5:$G$13,1)))/MAX(INDEX('Scratch Data'!$G$5:$G$13,MIN(MATCH($A6,'Scratch Data'!$G$5:$G$13,1)+1,ROWS('Scratch Data'!$G$5:$G$13)))-INDEX('Scratch Data'!$G$5:$G$13,MATCH($A6,'Scratch Data'!$G$5:$G$13,1)),0.0001))*Inputs!$B$15)*((INDEX('Scratch Data'!$J$5:$J$13,MATCH($A6,'Scratch Data'!$G$5:$G$13,1))+($A6-INDEX('Scratch Data'!$G$5:$G$13,MATCH($A6,'Scratch Data'!$G$5:$G$13,1)))*(INDEX('Scratch Data'!$J$5:$J$13,MIN(MATCH($A6,'Scratch Data'!$G$5:$G$13,1)+1,ROWS('Scratch Data'!$G$5:$G$13)))-INDEX('Scratch Data'!$J$5:$J$13,MATCH($A6,'Scratch Data'!$G$5:$G$13,1)))/MAX(INDEX('Scratch Data'!$G$5:$G$13,MIN(MATCH($A6,'Scratch Data'!$G$5:$G$13,1)+1,ROWS('Scratch Data'!$G$5:$G$13)))-INDEX('Scratch Data'!$G$5:$G$13,MATCH($A6,'Scratch Data'!$G$5:$G$13,1)),0.0001))+Inputs!$B$17)),(1+Inputs!$B$19*INDEX(Baseline!$B$3:$B$122,MATCH(MIN(MAX(ROUND((MAX($A6-Inputs!$B$22,30))/5,0)*5,5),600),Baseline!$A$3:$A$122,0))+(1-Inputs!$B$19)*INDEX(Baseline!$C$3:$C$122,MATCH(MIN(MAX(ROUND((MAX($A6-Inputs!$B$22,30))/5,0)*5,5),600),Baseline!$A$3:$A$122,0))+Inputs!$B$17)),(1+Inputs!$B$19*INDEX(Baseline!$B$3:$B$122,MATCH(MIN(MAX(ROUND((MAX($A6-Inputs!$B$22,30))/5,0)*5,5),600),Baseline!$A$3:$A$122,0))+(1-Inputs!$B$19)*INDEX(Baseline!$C$3:$C$122,MATCH(MIN(MAX(ROUND((MAX($A6-Inputs!$B$22,30))/5,0)*5,5),600),Baseline!$A$3:$A$122,0))+Inputs!$B$17))) -> 2.75 | E6: =1+Inputs!$B$24+0.6*INDEX(Baseline!$B$3:$B$122,MATCH(MIN(MAX(ROUND((MAX($A6-Inputs!$B$23,15))/5,0)*5,5),600),Baseline!$A$3:$A$122,0))+0.4*INDEX(Baseline!$C$3:$C$122,MATCH(MIN(MAX(ROUND((MAX($A6-Inputs!$B$23,15))/5,0)*5,5),600),Baseline!$A$3:$A$122,0)) -> 3.56 | H6: 4 | I6: =(INDEX('Scratch Data'!$E$5:$E$22,MATCH($H6,'Scratch Data'!$A$5:$A$22,1))+($H6-INDEX('Scratch Data'!$A$5:$A$22,MATCH($H6,'Scratch Data'!$A$5:$A$22,1)))*(INDEX('Scratch Data'!$E$5:$E$22,MIN(MATCH($H6,'Scratch Data'!$A$5:$A$22,1)+1,ROWS('Scratch Data'!$A$5:$A$22)))-INDEX('Scratch Data'!$E$5:$E$22,MATCH($H6,'Scratch Data'!$A$5:$A$22,1)))/MAX(INDEX('Scratch Data'!$A$5:$A$22,MIN(MATCH($H6,'Scratch Data'!$A$5:$A$22,1)+1,ROWS('Scratch Data'!$A$5:$A$22)))-INDEX('Scratch Data'!$A$5:$A$22,MATCH($H6,'Scratch Data'!$A$5:$A$22,1)),0.0001)) -> 1.161
